<?xml version="1.0"?>

<!-- 

# ===================================== COPYRIGHT ===================================== #
#                                                                                       #
#  IFRA (Intelligent Flexible Robotics and Assembly) Group, CRANFIELD UNIVERSITY        #
#  Created on behalf of the IFRA Group at Cranfield University, United Kingdom          #
#  E-mail: IFRA@cranfield.ac.uk                                                         #
#                                                                                       #
#  Licensed under the Apache-2.0 License.                                               #
#  You may not use this file except in compliance with the License.                     #
#  You may obtain a copy of the License at: http://www.apache.org/licenses/LICENSE-2.0  #
#                                                                                       #
#  Unless required by applicable law or agreed to in writing, software distributed      #
#  under the License is distributed on an "as-is" basis, without warranties or          #
#  conditions of any kind, either express or implied. See the License for the specific  #
#  language governing permissions and limitations under the License.                    #
#                                                                                       #
#  IFRA Group - Cranfield University                                                    #
#  AUTHORS: Mikel Bueno Viso - Mikel.Bueno-Viso@cranfield.ac.uk                         #
#           Dr. Seemal Asif  - s.asif@cranfield.ac.uk                                   #
#           Prof. Phil Webb  - p.f.webb@cranfield.ac.uk                                 #
#                                                                                       #
#  Date: April, 2023.                                                                   #
#                                                                                       #
# ===================================== COPYRIGHT ===================================== #

# ======= CITE OUR WORK ======= #
# You can cite our work with the following statement:
# IFRA-Cranfield (2023) ROS 2 Sim-to-Real Robot Control. URL: https://github.com/IFRA-Cranfield/ros2_SimRealRobotControl.

-->

<robot xmlns:xacro="http://ros.org/wiki/xacro">

  <!-- XACRO-MACRO of SCHUNK-EGP64: -->
  <xacro:macro name="egp64" params="bringup parent_link">

    <xacro:unless value="${bringup}">  
      
      <!-- SCHUNK-EGP64 TRANSMISSION: -->
      <xacro:include filename="$(find ros2srrc_endeffectors)/egp64/urdf/egp64_transmission.xacro" />
      <xacro:egp64_transmission />

    </xacro:unless>

    <!-- ***** SCHUNK EGP-64 GRIPPER .urdf SERIAL CHAIN ***** -->

    <!-- Schunk coupler (LINK): -->
    <link name="schunk_coupler">
      <visual>
        <geometry>
          <mesh filename="file://$(find ros2srrc_endeffectors)/egp64/meshes/egp64_Adapter.dae" />
        </geometry>
      </visual>
      <collision>
        <geometry>
          <mesh filename="file://$(find ros2srrc_endeffectors)/egp64/meshes/egp64_Adapter.dae" />
        </geometry>
      </collision>
      <inertial>
        <origin xyz="0 0 0" rpy="0 0 ${pi/2}" />
        <mass value="0.001" />
        <inertia ixx="0.001" ixy="0.0" ixz="0.0" iyy="0.001" iyz="0.0" izz="0.001"/>
      </inertial>
    </link>

    <!-- Schunk coupler (JOINT): -->
    <joint name="schunk_coupler_joint" type="fixed">
      <origin xyz="0 0 0.001" rpy="0 0 ${pi/2}" />
      <parent link="${parent_link}"/>
      <child link="schunk_coupler"/>
    </joint>
    <gazebo reference="schunk_coupler">
      <mu1>0.9</mu1>
      <mu2>0.9</mu2>
      <material>Gazebo/Black</material>
    </gazebo>

    <link name="egp64_gripper_base_link">
      <inertial>
        <origin xyz="0 0 0" rpy="0 0 0" />
        <mass value="0.005" />
        <inertia ixx="0.001" ixy="0.0" ixz="0.0" iyy="0.001" iyz="0.0" izz="0.001"/>
      </inertial>
      <visual>
        <geometry>
          <mesh filename="file://$(find ros2srrc_endeffectors)/egp64/meshes/egp64_BaseNoAdapter.dae" />
        </geometry>
        <material name="blue">
          <color rgba="0 0 1 1"/>
        </material>
      </visual>
      <collision>
        <geometry>
          <mesh filename="file://$(find ros2srrc_endeffectors)/egp64/meshes/egp64_BaseNoAdapter.dae" />
        </geometry>
        <material name="blue"/>
      </collision>
    </link>

    <joint name="egp64_coupler" type="fixed">
      <parent link="schunk_coupler"/>
      <child link="egp64_gripper_base_link"/>
      <origin xyz="-0.03205 0.01812 0.02047" rpy="0 0 0" />
    </joint>

    <!-- LEFT FINGER BASE -->
    
    <link name="egp64_finger_left_link">
      <inertial>
        <origin xyz="0.01483 -0.00782 0" rpy="0 0 0" />
        <mass value="0.002" />
        <inertia ixx="0.001" ixy="0.0" ixz="0.0" iyy="0.001" iyz="0.0" izz="0.001"/>
      </inertial>
      <visual>
        <geometry>
          <mesh filename="file://$(find ros2srrc_endeffectors)/egp64/meshes/egp64_LeftFingerBase.dae" />
        </geometry>
        <material name="black">
          <color rgba="0 0 0 1"/>
        </material>
      </visual>
      <collision>
        <geometry>
          <mesh filename="file://$(find ros2srrc_endeffectors)/egp64/meshes/egp64_LeftFingerBase.dae" />
        </geometry>
        <material name="black" />
      </collision>
    </link>
    
    <joint name="egp64_finger_left_joint" type="prismatic" >
      <parent link="egp64_gripper_base_link" />
      <child link="egp64_finger_left_link" />
      <limit effort="1000" lower="-0.001" upper="0.04" velocity="0.2"/>
      <origin xyz="0.01483 -0.00782 0" rpy="0 0 0" />
      <axis xyz="-1 0 0" />
      <dynamics damping="1.0" friction="1.0"/>
    </joint>
    
    <!-- LEFT FINGERTIP -->
    
    <link name="egp64_fingertip_left_link">
      <inertial>
        <origin xyz="0.03869 -0.0005 0.00093" rpy="0 0 0" />
        <mass value="0.001" />
        <inertia ixx="0.001" ixy="0.0" ixz="0.0" iyy="0.001" iyz="0.0" izz="0.001"/>
      </inertial>
      <visual>
        <geometry>
          <mesh filename="file://$(find ros2srrc_endeffectors)/egp64/meshes/egp64_LeftFinger.dae" />
        </geometry>
        <material name="silver">
          <color rgba="0.8 0.8 0.8 1"/>
        </material>
      </visual>
      <collision>
        <geometry>
          <mesh filename="file://$(find ros2srrc_endeffectors)/egp64/meshes/egp64_LeftFinger.dae" />
        </geometry>
        <material name="black"/>
      </collision>
    </link>
    
    <joint name="egp64_fingertip_left_joint" type="fixed" >
      <parent link="egp64_finger_left_link" />
      <child link="egp64_fingertip_left_link" />
      <origin xyz="0.03869 -0.0005 0.00093" rpy="0 0 0"/>
    </joint>

    
    <!-- RIGHT FINGER BASE -->

    <link name="egp64_finger_right_link">
      <inertial>
        <origin xyz="-0.0153 -0.00602 0" rpy="0 0 0" />
        <mass value="0.002" />
        <inertia ixx="0.001" ixy="0.0" ixz="0.0" iyy="0.001" iyz="0.0" izz="0.001"/>
      </inertial>
      <visual>
        <geometry>
          <mesh filename="file://$(find ros2srrc_endeffectors)/egp64/meshes/egp64_RightFingerBase.dae" />
        </geometry>
        <material name="black"/>
      </visual>
      <collision>
        <geometry>
          <mesh filename="file://$(find ros2srrc_endeffectors)/egp64/meshes/egp64_RightFingerBase.dae" />
        </geometry>
        <material name="black"/>
      </collision>
    </link>
    
    <joint name="egp64_finger_right_joint" type="prismatic" >
      <parent link="egp64_gripper_base_link" />
      <child link="egp64_finger_right_link" />
      <limit effort="1000" lower="-0.001" upper="0.04" velocity="0.2"/>
      <origin xyz="-0.0153 -0.00602 0" rpy="0 0 0" />
      <axis xyz="1 0 0" />
      <dynamics damping="1.0" friction="1.0"/>
    </joint>
    
    <!-- RIGHT FINGERTIP -->

    <link name="egp64_fingertip_right_link">
      <inertial>
        <origin xyz="-0.01211 -0.00197 0.00093" rpy="0 0 0" />
        <mass value="0.001" />
        <inertia ixx="0.001" ixy="0.0" ixz="0.0" iyy="0.001" iyz="0.0" izz="0.001"/>
      </inertial>
      <visual>
        <geometry>
          <mesh filename="file://$(find ros2srrc_endeffectors)/egp64/meshes/egp64_RightFinger.dae" />
        </geometry>
        <material name="silver" />
      </visual>
      <collision>
        <geometry>
          <mesh filename="file://$(find ros2srrc_endeffectors)/egp64/meshes/egp64_RightFinger.dae" />
        </geometry>
        <material name="black"/>
      </collision>
    </link>
    
    <joint name="egp64_fingertip_right_joint" type="fixed" >
      <parent link="egp64_finger_right_link" />
      <child link="egp64_fingertip_right_link" />
      <origin xyz="-0.01211 -0.00197 0.00093" rpy="0 0 0"/>
    </joint>

    <!-- SMALL CUBE FOR GRIPPER PLUGIN -->

    <link name="EE_egp64">
      <inertial>
        <origin xyz="0 0 0" rpy="0 0 0" />
        <mass value="0.00001" />
        <inertia ixx="0.001" ixy="0.0" ixz="0.0" iyy="0.001" iyz="0.0" izz="0.001"/>
      </inertial>
      <visual>
        <geometry>
          <box size= "0.001 0.001 0.001" />
        </geometry>
      </visual>
    </link>

    <joint name="EE_egp64_joint" type="fixed" >
      <parent link="${parent_link}" />
      <child link="EE_egp64" />
      <origin xyz="0.0 0.0 0.19" rpy="0 0 0"/>
    </joint>

    <gazebo reference="EE_egp64_joint">
      <preserveFixedJoint>true</preserveFixedJoint>
    </gazebo>
    
  </xacro:macro>
</robot>