<?xml version="1.0"?>

<!-- 

# ===================================== COPYRIGHT ===================================== #
#                                                                                       #
#  IFRA (Intelligent Flexible Robotics and Assembly) Group, CRANFIELD UNIVERSITY        #
#  Created on behalf of the IFRA Group at Cranfield University, United Kingdom          #
#  E-mail: IFRA@cranfield.ac.uk                                                         #
#                                                                                       #
#  Licensed under the Apache-2.0 License.                                               #
#  You may not use this file except in compliance with the License.                     #
#  You may obtain a copy of the License at: http://www.apache.org/licenses/LICENSE-2.0  #
#                                                                                       #
#  Unless required by applicable law or agreed to in writing, software distributed      #
#  under the License is distributed on an "as-is" basis, without warranties or          #
#  conditions of any kind, either express or implied. See the License for the specific  #
#  language governing permissions and limitations under the License.                    #
#                                                                                       #
#  IFRA Group - Cranfield University                                                    #
#  AUTHORS: Mikel Bueno Viso - Mikel.Bueno-Viso@cranfield.ac.uk                         #
#           Dr. Seemal Asif  - s.asif@cranfield.ac.uk                                   #
#           Prof. Phil Webb  - p.f.webb@cranfield.ac.uk                                 #
#                                                                                       #
#  Date: May, 2023.                                                                     #
#                                                                                       #
# ===================================== COPYRIGHT ===================================== #

# ===================================== COPYRIGHT ===================================== #
#                                                                                       #
#  Some of the information used to build the ROS2 UR3-Robot .urdf files in this ROS2    #
#  repository has been taken from the following resources:                              #
#       - Universal Robots ROS2 Description:                                            #
#         https://github.com/UniversalRobots/Universal_Robots_ROS2_Description          #
#       - Universal Robots ROS2 Gazebo Simulation:                                      #
#         https://github.com/UniversalRobots/Universal_Robots_ROS2_Gazebo_Simulation    #
#                                                                                       #
#  AUTHORS:                                                                             #
#       - ROS-Industrial - https://rosindustrial.org                                    #
#       - Universal Robots - https://github.com/UniversalRobots                         #
#       - Nadia Hammoudeh Garcia, Kelsey Hawkins, G.A. vd. Hoorn, Lovro Ivanov, Mathias #
#         Ludtke, Wim Meeussen, Felix Messmer, Miguel Prada Sarasola, Denis Stogl,      #
#         Andy Zelenak, Marvin Grosse Besselmann.                                       #
#       - Maintainers: Felix Exner (exner@fzi.de), Tristan Schnell (schnell@fzi.de),    #
#         Lovro Ivanov (lovro.ivanov@gmail.com), Denis Stogl (denis@stoglrobotics.de).  #
#                                                                                       #
#  Copyright (c) 2021, Universal Robots A/S                                             #
#  (ORIGINAL LICENSE) -> Licensed under the BSD 3-Clause License.                       #
#                                                                                       #
#  CHANGES MADE:                                                                        #
#  Robot information/specifications have been taken, and the code has been modified and #
#  re-organised in accordance with the ros2_SimRealRobotControl standards.              #
#                                                                                       #
# ===================================== COPYRIGHT ===================================== #

# ======= CITE OUR WORK ======= #
# You can cite our work with the following statement:
# IFRA-Cranfield (2023) ROS 2 Sim-to-Real Robot Control. URL: https://github.com/IFRA-Cranfield/ros2_SimRealRobotControl.

-->

<robot xmlns:xacro="http://ros.org/wiki/xacro">
  
  <!-- Include UR3 ROBOT SPECIFICATIONS: -->
  <xacro:include filename="$(find ros2srrc_ur3_gazebo)/urdf/ur3_common.xacro" />

  <!-- XACRO-MACRO of UR3: -->
  <xacro:macro name="ur3" params="prefix EE_no EE_robotiq bringup robot_ip script_filename input_recipe_filename output_recipe_filename">

    <!-- LOAD UR3-Common: -->
    <xacro:ur3_common/>

    <!-- UR3 TRANSMISSION: -->
    <xacro:unless value="${bringup}">  
      <xacro:include filename="$(find ros2srrc_ur3_gazebo)/urdf/ur3_transmission.xacro" />
      <xacro:ur3_transmission 
        prefix=""
        EE_robotiq="${EE_robotiq}" 
      />
    </xacro:unless>

    <!-- UR3 - ROS2_CONTROL: -->
    <xacro:include filename="$(find ros2srrc_ur3_gazebo)/urdf/ur3_ros2control.xacro" />
    <xacro:ur3_ros2control 
      prefix="" 
      EE_no="${EE_no}"
      EE_robotiq="${EE_robotiq}"
      bringup="${bringup}"
      robot_ip="${robot_ip}"
      script_filename="${script_filename}"
      input_recipe_filename="${input_recipe_filename}"
      output_recipe_filename="${output_recipe_filename}"/>

    <!-- ***** UR3 ROBOT .urdf SERIAL CHAIN ***** -->

    <!-- Links: -->
    <link name="${prefix}base_link"/>
    <link name="${prefix}base_link_inertia">
      <visual>
        <origin xyz="0 0 0" rpy="0 0 ${pi}"/>
        <geometry>
          <mesh filename="file://$(find ros2srrc_ur3_gazebo)/meshes/visual/base.dae"/>
        </geometry>
        <material name="LightGrey">
          <color rgba="0.7 0.7 0.7 1.0"/>
        </material>
      </visual>
      <collision>
        <origin xyz="0 0 0" rpy="0 0 ${pi}"/>
        <geometry>
          <mesh filename="file://$(find ros2srrc_ur3_gazebo)/meshes/collision/base.stl"/>
        </geometry>
      </collision>
      <xacro:cylinder_inertial radius="${base_inertia_radius}" length="${base_inertia_length}" mass="${base_mass}">
        <origin xyz="0 0 0" rpy="0 0 0" />
      </xacro:cylinder_inertial>
    </link>
    <link name="${prefix}shoulder_link">
      <visual>
        <origin xyz="0 0 0" rpy="0 0 ${pi}"/>
        <geometry>
          <mesh filename="file://$(find ros2srrc_ur3_gazebo)/meshes/visual/shoulder.dae"/>
        </geometry>
        <material name="LightGrey">
          <color rgba="0.7 0.7 0.7 1.0"/>
        </material>
      </visual>
      <collision>
        <origin xyz="0 0 0" rpy="0 0 ${pi}"/>
        <geometry>
          <mesh filename="file://$(find ros2srrc_ur3_gazebo)/meshes/collision/shoulder.stl"/>
        </geometry>
      </collision>
      <xacro:cylinder_inertial radius="${shoulder_inertia_radius}" length="${shoulder_inertia_length}" mass="${shoulder_mass}">
        <origin xyz="0 0 0" rpy="0 0 0" />
      </xacro:cylinder_inertial>
    </link>
    <link name="${prefix}upper_arm_link">
      <visual>
        <origin xyz="0 0 ${shoulder_offset}" rpy="${pi/2} 0 ${-pi/2}"/>
        <geometry>
          <mesh filename="file://$(find ros2srrc_ur3_gazebo)/meshes/visual/upperarm.dae"/>
        </geometry>
        <material name="LightGrey">
          <color rgba="0.7 0.7 0.7 1.0"/>
        </material>
      </visual>
      <collision>
        <origin xyz="0 0 ${shoulder_offset}" rpy="${pi/2} 0 ${-pi/2}"/>
        <geometry>
          <mesh filename="file://$(find ros2srrc_ur3_gazebo)/meshes/collision/upperarm.stl"/>
        </geometry>
      </collision>
      <xacro:cylinder_inertial radius="${upperarm_inertia_radius}" length="${upperarm_inertia_length}" mass="${upper_arm_mass}">
        <origin xyz="${-0.5 * upperarm_inertia_length} 0.0 ${upper_arm_inertia_offset}" rpy="0 ${pi/2} 0" />
      </xacro:cylinder_inertial>
    </link>
    <link name="${prefix}forearm_link">
      <visual>
        <origin xyz="0 0 ${elbow_offset}" rpy="${pi/2} 0 ${-pi/2}"/>
        <geometry>
          <mesh filename="file://$(find ros2srrc_ur3_gazebo)/meshes/visual/forearm.dae"/>
        </geometry>
        <material name="LightGrey">
          <color rgba="0.7 0.7 0.7 1.0"/>
        </material>
      </visual>
      <collision>
        <origin xyz="0 0 ${elbow_offset}" rpy="${pi/2} 0 ${-pi/2}"/>
        <geometry>
          <mesh filename="file://$(find ros2srrc_ur3_gazebo)/meshes/collision/forearm.stl"/>
        </geometry>
      </collision>
      <xacro:cylinder_inertial radius="${forearm_inertia_radius}" length="${forearm_inertia_length}"  mass="${forearm_mass}">
        <origin xyz="${-0.5 * forearm_inertia_length} 0.0 ${elbow_offset}" rpy="0 ${pi/2} 0" />
      </xacro:cylinder_inertial>
    </link>
    <link name="${prefix}wrist_1_link">
      <visual>
        <origin xyz="0 0 ${wrist_1_visual_offset}" rpy="${pi/2} 0 0"/>
        <geometry>
          <mesh filename="file://$(find ros2srrc_ur3_gazebo)/meshes/visual/wrist1.dae"/>
        </geometry>
        <material name="LightGrey">
          <color rgba="0.7 0.7 0.7 1.0"/>
        </material>
      </visual>
      <collision>
        <origin xyz="0 0 ${wrist_1_visual_offset}" rpy="${pi/2} 0 0"/>
        <geometry>
          <mesh filename="file://$(find ros2srrc_ur3_gazebo)/meshes/collision/wrist1.stl"/>
        </geometry>
      </collision>
      <xacro:cylinder_inertial radius="${wrist_1_inertia_radius}" length="${wrist_1_inertia_length}"  mass="${wrist_1_mass}">
        <origin xyz="0 0 0" rpy="0 0 0" />
      </xacro:cylinder_inertial>
    </link>
    <link name="${prefix}wrist_2_link">
      <visual>
        <origin xyz="0 0 ${wrist_2_visual_offset}" rpy="0 0 0"/>
        <geometry>
          <mesh filename="file://$(find ros2srrc_ur3_gazebo)/meshes/visual/wrist2.dae"/>
        </geometry>
        <material name="LightGrey">
          <color rgba="0.7 0.7 0.7 1.0"/>
        </material>
      </visual>
      <collision>
        <origin xyz="0 0 ${wrist_2_visual_offset}" rpy="0 0 0"/>
        <geometry>
          <mesh filename="file://$(find ros2srrc_ur3_gazebo)/meshes/collision/wrist2.stl"/>
        </geometry>
      </collision>
      <xacro:cylinder_inertial radius="${wrist_2_inertia_radius}" length="${wrist_2_inertia_length}"  mass="${wrist_2_mass}">
        <origin xyz="0 0 0" rpy="0 0 0" />
      </xacro:cylinder_inertial>
    </link>
    <link name="${prefix}wrist_3_link">
      <visual>
        <origin xyz="0 0 ${wrist_3_visual_offset}" rpy="${pi/2} 0 0"/>
        <geometry>
          <mesh filename="file://$(find ros2srrc_ur3_gazebo)/meshes/visual/wrist3.dae"/>
        </geometry>
        <material name="LightGrey">
          <color rgba="0.7 0.7 0.7 1.0"/>
        </material>
      </visual>
      <collision>
        <origin xyz="0 0 ${wrist_3_visual_offset}" rpy="${pi/2} 0 0"/>
        <geometry>
          <mesh filename="file://$(find ros2srrc_ur3_gazebo)/meshes/collision/wrist3.stl"/>
        </geometry>
      </collision>
      <xacro:cylinder_inertial radius="${wrist_3_inertia_radius}" length="${wrist_3_inertia_length}"  mass="${wrist_3_mass}">
        <origin xyz="0.0 0.0 ${-0.5 * wrist_3_inertia_length}" rpy="0 0 0" />
      </xacro:cylinder_inertial>
    </link>

    <!-- Joints: -->
    <joint name="${prefix}base_link-base_link_inertia" type="fixed">
      <parent link="${prefix}base_link" />
      <child link="${prefix}base_link_inertia" />
      <!-- 'base_link' is REP-103 aligned (so X+ forward), while the internal
           frames of the robot/controller have X+ pointing backwards.
           Use the joint between 'base_link' and 'base_link_inertia' (a dummy
           link/frame) to introduce the necessary rotation over Z (of pi rad).
      -->
      <origin xyz="0 0 0" rpy="0 0 ${pi}" />
    </joint>
    <joint name="${prefix}shoulder_pan_joint" type="revolute">
      <parent link="${prefix}base_link_inertia" />
      <child link="${prefix}shoulder_link" />
      <origin xyz="${shoulder_x} ${shoulder_y} ${shoulder_z}" rpy="${shoulder_roll} ${shoulder_pitch} ${shoulder_yaw}" />
      <axis xyz="0 0 1" />
      <limit lower="${shoulder_pan_lower_limit}" upper="${shoulder_pan_upper_limit}"
        effort="${shoulder_pan_effort_limit}" velocity="${shoulder_pan_velocity_limit}"/>
      <dynamics damping="1.0" friction="100.0"/>
    </joint>
    <joint name="${prefix}shoulder_lift_joint" type="revolute">
      <parent link="${prefix}shoulder_link" />
      <child link="${prefix}upper_arm_link" />
      <origin xyz="${upper_arm_x} ${upper_arm_y} ${upper_arm_z}" rpy="${upper_arm_roll} ${upper_arm_pitch} ${upper_arm_yaw}" />
      <axis xyz="0 0 1" />
      <limit lower="${shoulder_lift_lower_limit}" upper="${shoulder_lift_upper_limit}"
        effort="${shoulder_lift_effort_limit}" velocity="${shoulder_lift_velocity_limit}"/>
      <dynamics damping="1.0" friction="100.0"/>
    </joint>
    <joint name="${prefix}elbow_joint" type="revolute">
      <parent link="${prefix}upper_arm_link" />
      <child link="${prefix}forearm_link" />
      <origin xyz="${forearm_x} ${forearm_y} ${forearm_z}" rpy="${forearm_roll} ${forearm_pitch} ${forearm_yaw}" />
      <axis xyz="0 0 1" />
      <limit lower="${elbow_joint_lower_limit}" upper="${elbow_joint_upper_limit}"
        effort="${elbow_joint_effort_limit}" velocity="${elbow_joint_velocity_limit}"/>
      <dynamics damping="1.0" friction="100.0"/>
    </joint>
    <joint name="${prefix}wrist_1_joint" type="revolute">
      <parent link="${prefix}forearm_link" />
      <child link="${prefix}wrist_1_link" />
      <origin xyz="${wrist_1_x} ${wrist_1_y} ${wrist_1_z}" rpy="${wrist_1_roll} ${wrist_1_pitch} ${wrist_1_yaw}" />
      <axis xyz="0 0 1" />
      <limit lower="${wrist_1_lower_limit}" upper="${wrist_1_upper_limit}"
        effort="${wrist_1_effort_limit}" velocity="${wrist_1_velocity_limit}"/>
      <dynamics damping="1.0" friction="10.0"/>
    </joint>
    <joint name="${prefix}wrist_2_joint" type="revolute">
      <parent link="${prefix}wrist_1_link" />
      <child link="${prefix}wrist_2_link" />
      <origin xyz="${wrist_2_x} ${wrist_2_y} ${wrist_2_z}" rpy="${wrist_2_roll} ${wrist_2_pitch} ${wrist_2_yaw}" />
      <axis xyz="0 0 1" />
      <limit lower="${wrist_2_lower_limit}" upper="${wrist_2_upper_limit}"
             effort="${wrist_2_effort_limit}" velocity="${wrist_2_velocity_limit}"/>
      <dynamics damping="1.0" friction="10.0"/>
    </joint>
    <joint name="${prefix}wrist_3_joint" type="revolute">
      <parent link="${prefix}wrist_2_link" />
      <child link="${prefix}wrist_3_link" />
      <origin xyz="${wrist_3_x} ${wrist_3_y} ${wrist_3_z}" rpy="${wrist_3_roll} ${wrist_3_pitch} ${wrist_3_yaw}" />
      <axis xyz="0 0 1" />
      <limit lower="${wrist_3_lower_limit}" upper="${wrist_3_upper_limit}"
             effort="${wrist_3_effort_limit}" velocity="${wrist_3_velocity_limit}"/>
      <dynamics damping="1.0" friction="1.0"/>
    </joint>

    <!-- ROS-Industrial 'base' frame - base_link to UR 'Base' Coordinates transform -->
    <link name="${prefix}base"/>
    <joint name="${prefix}base_link-base_fixed_joint" type="fixed">
      <!-- Note the rotation over Z of pi radians - as base_link is REP-103
           aligned (i.e., has X+ forward, Y+ left and Z+ up), this is needed
           to correctly align 'base' with the 'Base' coordinate system of
           the UR controller.
      -->
      <origin xyz="0 0 0" rpy="0 0 ${pi}"/>
      <parent link="${prefix}base_link"/>
      <child link="${prefix}base"/>
    </joint>

    <!-- ROS-Industrial 'flange' frame - attachment point for EEF models -->
    <link name="${prefix}flange" />
    <joint name="${prefix}wrist_3-flange" type="fixed">
      <parent link="${prefix}wrist_3_link" />
      <child link="${prefix}flange" />
      <origin xyz="0 0 0" rpy="0 ${-pi/2.0} ${-pi/2.0}" />
    </joint>

    <!-- ROS-Industrial 'tool0' frame - all-zeros tool frame -->
    <link name="${prefix}tool0"/>
    <joint name="${prefix}flange-tool0" type="fixed">
      <!-- default toolframe - X+ left, Y+ up, Z+ front -->
      <origin xyz="0 0 0" rpy="${pi/2.0} 0 ${pi/2.0}"/>
      <parent link="${prefix}flange"/>
      <child link="${prefix}tool0"/>
    </joint>


    <!-- =================================== -->
    <!-- ========== END-EFFECTORS ========== -->

    <!-- === ROBOTIQ 2f-85 GRIPPER === -->
    <xacro:if value="${EE_robotiq}">

      <!-- NOTE: JOINT LIMITS have been slightly augmentated from 0.0 to +-0.05 to avoid errors in MoveIt!2 execution. -->

      <!-- Robotiq: coupler -->
      <link name="robotiq_coupler">
        <visual>
          <geometry>
            <mesh filename="file://$(find ros2srrc_ur3_gazebo)/meshes/robotiq2f85/robotiq_85_coupler.stl" />
          </geometry>
        </visual>
        <collision>
          <geometry>
            <mesh filename="file://$(find ros2srrc_ur3_gazebo)/meshes/robotiq2f85/robotiq_85_coupler.stl" />
          </geometry>
        </collision>
        <inertial>
          <origin xyz="2.073e-05   1.45286e-03  -1.1049e-03" rpy="0 0 0" />
          <mass value="0.168" />
          <inertia ixx="6.69695624e-05" ixy="5.21511788e-09" ixz="-2.74383009e-08" 
                  iyy="7.85088161e-05" iyz="5.41105193e-07" izz="1.41819717e-04"/>
        </inertial>
      </link>

      <joint name="robotiq_coupler_joint" type="fixed">
        <origin xyz="0 0 0.004" rpy="0 0 ${-pi/2.0}" />
        <parent link="tool0"/>
        <child link="robotiq_coupler"/>
      </joint>

      <gazebo reference="robotiq_coupler">
        <mu1>0.9</mu1>
        <mu2>0.9</mu2>
        <material>Gazebo/FlatBlack</material>
      </gazebo>

      <!-- Robotiq: base_link -->
      <link name="${prefix}robotiq_85_base_link">
        <visual>
          <geometry>
            <mesh filename="file://$(find ros2srrc_ur3_gazebo)/meshes/robotiq2f85/visual/robotiq_85_base_link.dae"/>
          </geometry>
        </visual>
        <collision>
          <geometry>
            <mesh filename="file://$(find ros2srrc_ur3_gazebo)/meshes/robotiq2f85/collision/robotiq_85_base_link.stl"/>
          </geometry>
        </collision>
        <inertial>
          <mass value="0.636951" />
          <origin xyz="0.0 0.0 0.0" />
          <inertia ixx = "0.000380" ixy = "0.000000" ixz = "0.000000"
              iyx = "0.000000" iyy = "0.001110" iyz = "0.000000"
              izx = "0.000000" izy = "0.000000" izz = "0.001171" />
        </inertial>
      </link>

      <joint name="${prefix}robotiq_85_base_joint" type="fixed">
        <origin xyz="0 0 0.004" rpy="0 ${-pi/2} ${pi}"/>
        <parent link="robotiq_coupler"/>
        <child link="${prefix}robotiq_85_base_link"/>
      </joint>

      <!-- Robotiq: left_knuckle -->
      <link name="${prefix}robotiq_85_left_knuckle_link">
        <visual>
          <geometry>
            <mesh filename="file://$(find ros2srrc_ur3_gazebo)/meshes/robotiq2f85/visual/robotiq_85_knuckle_link.dae"/>
          </geometry>
        </visual>
        <collision>
          <geometry>
            <mesh filename="file://$(find ros2srrc_ur3_gazebo)/meshes/robotiq2f85/collision/robotiq_85_knuckle_link.stl"/>
          </geometry>
        </collision>
        <inertial>
          <mass value="0.018491" />
          <origin xyz="0.0 0.0 0.0" />
          <inertia ixx = "0.000009" ixy = "-0.000001" ixz = "0.000000"
              iyx = "-0.000001" iyy = "0.000001" iyz = "0.000000"
              izx = "0.000000" izy = "0.000000" izz = "0.000010" />
        </inertial>
      </link>

      <joint name="${prefix}robotiq_85_left_knuckle_joint" type="revolute">
	      <parent link="${prefix}robotiq_85_base_link"/>
	      <child link="${prefix}robotiq_85_left_knuckle_link"/>
	      <axis xyz="0 0 1"/>
	      <origin rpy="${pi} 0.0 0.0" xyz="0.05490451627 0.03060114443 0.0"/>
	      <limit lower="-0.05" upper="0.80285" velocity="0.5" effort="1000"/>
        <dynamics damping="1.0" friction="1.0"/>
	    </joint>

      <!-- Robotiq: right_knuckle -->
      <link name="${prefix}robotiq_85_right_knuckle_link">
        <visual>
          <geometry>
            <mesh filename="file://$(find ros2srrc_ur3_gazebo)/meshes/robotiq2f85/visual/robotiq_85_knuckle_link.dae"/>
          </geometry>
        </visual>
        <collision>
          <geometry>
            <mesh filename="file://$(find ros2srrc_ur3_gazebo)/meshes/robotiq2f85/collision/robotiq_85_knuckle_link.stl"/>
          </geometry>
        </collision>
        <inertial>
          <mass value="0.018491" />
          <origin xyz="0.0 0.0 0.0" />
          <inertia ixx = "0.000009" ixy = "-0.000001" ixz = "0.000000"
              iyx = "-0.000001" iyy = "0.000001" iyz = "0.000000"
              izx = "0.000000" izy = "0.000000" izz = "0.000010" />
        </inertial>
      </link>

      <joint name="${prefix}robotiq_85_right_knuckle_joint" type="continuous">
        <parent link="${prefix}robotiq_85_base_link"/>
        <child link="${prefix}robotiq_85_right_knuckle_link"/>
        <axis xyz="0 0 1"/>
        <origin rpy="0.0 0.0 0.0" xyz="0.05490451627 -0.03060114443 0.0"/>
        <limit lower="-0.05" upper="0.80285" velocity="0.5" effort="1000"/>
        <dynamics damping="1.0" friction="1.0"/>
      </joint>

      <!-- Robotiq: left_finger -->
      <link name="${prefix}robotiq_85_left_finger_link">
        <visual>
          <geometry>
            <mesh filename="file://$(find ros2srrc_ur3_gazebo)/meshes/robotiq2f85/visual/robotiq_85_finger_link.dae"/>
          </geometry>
        </visual>
        <collision>
          <geometry>
            <mesh filename="file://$(find ros2srrc_ur3_gazebo)/meshes/robotiq2f85/collision/robotiq_85_finger_link.stl"/>
          </geometry>
        </collision>
        <inertial>
          <mass value="0.027309" />
          <origin xyz="0.0 0.0 0.0" />
          <inertia ixx = "0.000003" ixy = "-0.000002" ixz = "0.000000"
              iyx = "-0.000002" iyy = "0.000021" iyz = "0.000000"
              izx = "0.000000" izy = "0.000000" izz = "0.000020" />
        </inertial>
      </link>

      <joint name="${prefix}robotiq_85_left_finger_joint" type="fixed">
        <parent link="${prefix}robotiq_85_left_knuckle_link"/>
        <child link="${prefix}robotiq_85_left_finger_link"/>
        <origin xyz="-0.00408552455 -0.03148604435 0.0" rpy="0 0 0" />
        <dynamics damping="1.0" friction="1.0"/>
      </joint>

      <!-- Robotiq: right_finger -->
      <link name="${prefix}robotiq_85_right_finger_link">
        <visual>
          <geometry>
            <mesh filename="file://$(find ros2srrc_ur3_gazebo)/meshes/robotiq2f85/visual/robotiq_85_finger_link.dae"/>
          </geometry>
        </visual>
        <collision>
          <geometry>
            <mesh filename="file://$(find ros2srrc_ur3_gazebo)/meshes/robotiq2f85/collision/robotiq_85_finger_link.stl"/>
          </geometry>
        </collision>
        <inertial>
          <mass value="0.027309" />
          <origin xyz="0.0 0.0 0.0" />
          <inertia ixx = "0.000003" ixy = "-0.000002" ixz = "0.000000"
              iyx = "-0.000002" iyy = "0.000021" iyz = "0.000000"
              izx = "0.000000" izy = "0.000000" izz = "0.000020" />
        </inertial>
      </link>

      <joint name="${prefix}robotiq_85_right_finger_joint" type="fixed">
        <parent link="${prefix}robotiq_85_right_knuckle_link"/>
        <child link="${prefix}robotiq_85_right_finger_link"/>
        <origin xyz="-0.00408552455 -0.03148604435 0.0" rpy="0 0 0" />
        <dynamics damping="1.0" friction="1.0"/>
      </joint>

      <!-- Robotiq: left_inner_knuckle -->
      <link name="${prefix}robotiq_85_left_inner_knuckle_link">
        <visual>
          <geometry>
            <mesh filename="file://$(find ros2srrc_ur3_gazebo)/meshes/robotiq2f85/visual/robotiq_85_inner_knuckle_link.dae"/>
          </geometry>
        </visual>
        <collision>
          <geometry>
            <mesh filename="file://$(find ros2srrc_ur3_gazebo)/meshes/robotiq2f85/collision/robotiq_85_inner_knuckle_link.stl"/>
          </geometry>
        </collision>
        <inertial>
          <mass value="0.029951" />
          <origin xyz="0.0 0.0 0.0" />
          <inertia ixx = "0.000039" ixy = "0.000000" ixz = "0.000000"
              iyx = "0.000000" iyy = "0.000005" iyz = "0.000000"
              izx = "0.000000" izy = "0.000000" izz = "0.000035" />
        </inertial>
      </link>

      <joint name="${prefix}robotiq_85_left_inner_knuckle_joint" type="continuous">
        <parent link="${prefix}robotiq_85_base_link"/>
        <child link="${prefix}robotiq_85_left_inner_knuckle_link"/>
        <axis xyz="0 0 1"/>
        <origin xyz="0.06142 0.0127 0" rpy="${pi} 0.0 0.0" />
        <limit lower="-0.05" upper="0.80285" velocity="0.5" effort="1000"/>
        <dynamics damping="1.0" friction="1.0"/>
      </joint>

      <!-- Robotiq: right_inner_knuckle -->
      <link name="${prefix}robotiq_85_right_inner_knuckle_link">
        <visual>
          <geometry>
            <mesh filename="file://$(find ros2srrc_ur3_gazebo)/meshes/robotiq2f85/visual/robotiq_85_inner_knuckle_link.dae"/>
          </geometry>
        </visual>
        <collision>
          <geometry>
            <mesh filename="file://$(find ros2srrc_ur3_gazebo)/meshes/robotiq2f85/collision/robotiq_85_inner_knuckle_link.stl"/>
          </geometry>
        </collision>
        <inertial>
          <mass value="0.029951" />
          <origin xyz="0.0 0.0 0.0" />
          <inertia ixx = "0.000039" ixy = "0.000000" ixz = "0.000000"
              iyx = "0.000000" iyy = "0.000005" iyz = "0.000000"
              izx = "0.000000" izy = "0.000000" izz = "0.000035" />
        </inertial>
      </link>

      <joint name="${prefix}robotiq_85_right_inner_knuckle_joint" type="continuous">
        <parent link="${prefix}robotiq_85_base_link"/>
        <child link="${prefix}robotiq_85_right_inner_knuckle_link"/>
        <axis xyz="0 0 1"/>
        <origin xyz="0.06142 -0.0127 0" rpy="0 0 0"/>
        <limit lower="-0.05" upper="0.80285" velocity="0.5" effort="1000"/>
        <dynamics damping="1.0" friction="1.0"/>
      </joint>

      <!-- Robotiq: left_finger_tip -->
      <link name="${prefix}robotiq_85_left_finger_tip_link">
        <visual>
          <geometry>
            <mesh filename="file://$(find ros2srrc_ur3_gazebo)/meshes/robotiq2f85/visual/robotiq_85_finger_tip_link.dae"/>
          </geometry>
        </visual>
        <collision>
          <geometry>
            <mesh filename="file://$(find ros2srrc_ur3_gazebo)/meshes/robotiq2f85/collision/robotiq_85_finger_tip_link.stl"/>
          </geometry>
        </collision>
        <inertial>
          <mass value="0.019555" />
          <origin xyz="0.0 0.0 0.0" />
          <inertia ixx = "0.000002" ixy = "0.000000" ixz = "0.000000"
              iyx = "0.000000" iyy = "0.000005" iyz = "0.000000"
              izx = "0.000000" izy = "0.000000" izz = "0.000006" />
        </inertial>
      </link> 

      <joint name="${prefix}robotiq_85_left_finger_tip_joint" type="continuous">
        <parent link="${prefix}robotiq_85_left_inner_knuckle_link"/>
        <child link="${prefix}robotiq_85_left_finger_tip_link"/>
        <axis xyz="0 0 1"/>
        <origin xyz="0.04303959807 -0.03759940821 0.0" rpy="0.0 0.0 0.0"/>
        <limit lower="-0.80285" upper="0.05" velocity="0.5" effort="1000"/>
        <dynamics damping="1.0" friction="1.0"/>
      </joint>

      <!-- Robotiq: right_finger_tip -->
      <link name="${prefix}robotiq_85_right_finger_tip_link">
        <visual>
          <geometry>
            <mesh filename="file://$(find ros2srrc_ur3_gazebo)/meshes/robotiq2f85/visual/robotiq_85_finger_tip_link.dae"/>
          </geometry>
        </visual>
        <collision>
          <geometry>
            <mesh filename="file://$(find ros2srrc_ur3_gazebo)/meshes/robotiq2f85/collision/robotiq_85_finger_tip_link.stl"/>
          </geometry>
        </collision>
        <inertial>
          <mass value="0.019555" />
          <origin xyz="0.0 0.0 0.0" />
          <inertia ixx = "0.000002" ixy = "0.000000" ixz = "0.000000"
              iyx = "0.000000" iyy = "0.000005" iyz = "0.000000"
              izx = "0.000000" izy = "0.000000" izz = "0.000006" />
        </inertial>
      </link>

      <joint name="${prefix}robotiq_85_right_finger_tip_joint" type="continuous">
        <parent link="${prefix}robotiq_85_right_inner_knuckle_link"/>
        <child link="${prefix}robotiq_85_right_finger_tip_link"/>
        <axis xyz="0 0 1"/>
        <origin rpy="0.0 0.0 0.0" xyz="0.04303959807 -0.03759940821  0.0"/>
        <limit lower="-0.80285" upper="0.05" velocity="0.5" effort="1000"/>
        <dynamics damping="1.0" friction="1.0"/>
      </joint>

    </xacro:if>
    <!-- === ROBOTIQ 2f-85 GRIPPER === -->

    <!-- ========== END-EFFECTORS ========== -->

  </xacro:macro>
</robot>